Workbook

Sheet Sheet1
A1: id | B1: dateExpiration | C1: category | D1: Type | E1: name | F1: dateCreation | G1: file
A2: 4519252 | C2: Resume | D2: =IFERROR(INDEX(Types!B:B, MATCH(C2,Types!A:A, 0)), "") -> CV | E2: resume.doc | F2: 2010-08-20 10:21:29 | G2: attachments/4459036.doc
A3: 4519263 | C3: Resume | D3: =IFERROR(INDEX(Types!B:B, MATCH(C3,Types!A:A, 0)), "") -> CV | E3: MigratedCV_1.doc | F3: 2007-09-15 19:05:29 | G3: attachments/4966312.doc
A4: 4519266 | C4: Resume | D4: =IFERROR(INDEX(Types!B:B, MATCH(C4,Types!A:A, 0)), "") -> CV | E4: Resume.Andrew Bailey. March 01. 2017.docx | F4: 2017-03-02 11:55:13 | G4: attachments/4459403.docx
A5: 4519266 | C5: License Document | D5: =IFERROR(INDEX(Types!B:B, MATCH(C5,Types!A:A, 0)), "") -> CoC | E5: updated firefighting.jpg | F5: 2017-03-02 11:55:12 | G5: attachments/4459402.jpg
A6: 4519266 | C6: Other Resume | D6: =IFERROR(INDEX(Types!B:B, MATCH(C6,Types!A:A, 0)), "") -> Other | E6: Resume,Andrew Bailey. May 2016.doc | F6: 2016-05-25 07:26:53 | G6: attachments/4459401.doc
A7: 4519266 | C7: License Document | D7: =IFERROR(INDEX(Types!B:B, MATCH(C7,Types!A:A, 0)), "") -> CoC | E7: ENG 1 Malta.jpg | F7: 2014-04-28 08:31:28 | G7: attachments/4459400.jpg
A8: 4519266 | C8: Verified Documents | D8: =IFERROR(INDEX(Types!B:B, MATCH(C8,Types!A:A, 0)), "") -> Verified Licences | E8: B1B2 copy.jpg | F8: 2014-04-28 08:30:47 | G8: attachments/4459399.jpg
A9: 4519266 | C9: Other Resume | D9: =IFERROR(INDEX(Types!B:B, MATCH(C9,Types!A:A, 0)), "") -> Other | E9: Resume,Andrew Bailey. Compressed version, 4 8 2014.doc | F9: 2014-04-24 09:35:48 | G9: attachments/4459398.doc
A10: 4519266 | C10: Other Resume | D10: =IFERROR(INDEX(Types!B:B, MATCH(C10,Types!A:A, 0)), "") -> Other | E10: Resume,Andrew Bailey. Compressed version, 4 9 2012.doc | F10: 2013-05-20 09:38:55 | G10: attachments/4459397.doc
A11: 4519266 | C11: Other Resume | D11: =IFERROR(INDEX(Types!B:B, MATCH(C11,Types!A:A, 0)), "") -> Other | E11: Resume,Andrew Bailey. Compressed version, 4 9 2012.doc | F11: 2012-05-01 09:45:32 | G11: attachments/4459396.doc
A12: 4519266 | C12: References | D12: =IFERROR(INDEX(Types!B:B, MATCH(C12,Types!A:A, 0)), "") -> Reference | E12: Spirit Ref Dale.jpg | F12: 2012-04-10 10:31:15 | G12: attachments/4459395.jpg
A13: 4519266 | C13: File | D13: =IFERROR(INDEX(Types!B:B, MATCH(C13,Types!A:A, 0)), "") -> Other | E13: Reference List for Andrew Bailey.docx | F13: 2012-04-10 07:28:49 | G13: attachments/4459370.docx
... A48: 4519376 | C48: Reference | D48: =IFERROR(INDEX(Types!B:B, MATCH(C48,Types!A:A, 0)), "") -> Reference | E48: Reference from Owners of Motor Yacht Domani.docx | F48: 2021-04-16 20:44:38 | G48: attachments/15223789.docx
A49: 4519376 | B49: 2022-05-09 00:00:00 | C49: Deck License | D49: =IFERROR(INDEX(Types!B:B, MATCH(C49,Types!A:A, 0)), "") -> CoC | E49: CoC. all pages. Peter Pexton.pdf | F49: 2021-04-16 20:44:37 | G49: attachments/15223787.pdf
A50: 4519376 | C50: Resume | D50: =IFERROR(INDEX(Types!B:B, MATCH(C50,Types!A:A, 0)), "") -> CV | E50: CAPTAIN_PETER_PEXTON_CV.pdf | F50: 2021-04-16 20:39:37 | G50: attachments/15223761.pdf
A51: 4519376 | C51: Resume | D51: =IFERROR(INDEX(Types!B:B, MATCH(C51,Types!A:A, 0)), "") -> CV | E51: CAPTAIN_PETER_PEXTON_CV.pdf | F51: 2021-04-15 23:02:51 | G51: attachments/15215697.pdf
A52: 4519376 | C52: Resume | D52: =IFERROR(INDEX(Types!B:B, MATCH(C52,Types!A:A, 0)), "") -> CV | E52: MigratedCV_1.doc | F52: 2007-09-15 19:03:02 | G52: attachments/4462811.doc
A53: 4519389 | C53: Resume | D53: =IFERROR(INDEX(Types!B:B, MATCH(C53,Types!A:A, 0)), "") -> CV | E53: PUCCI CAPTAINwpic.docx | F53: 2018-07-25 18:43:10 | G53: attachments/4463056.docx
A54: 4519389 | C54: Other Resume | D54: =IFERROR(INDEX(Types!B:B, MATCH(C54,Types!A:A, 0)), "") -> Other | E54: puccicaptainres15.docx | F54: 2018-07-25 18:41:07 | G54: attachments/4463055.docx
A55: 4519389 | C55: Other Resume | D55: =IFERROR(INDEX(Types!B:B, MATCH(C55,Types!A:A, 0)), "") -> Other | E55: lpucciNAresumed3.23.docx | F55: 2018-04-03 12:25:46 | G55: attachments/4463054.docx
A56: 4519389 | C56: Other Resume | D56: =IFERROR(INDEX(Types!B:B, MATCH(C56,Types!A:A, 0)), "") -> Other | E56: lpucciNAresumed3.23.docx | F56: 2018-03-27 17:40:27 | G56: attachments/4463053.docx
A57: 4519389 | C57: Other Resume | D57: =IFERROR(INDEX(Types!B:B, MATCH(C57,Types!A:A, 0)), "") -> Other | E57: PUCCI CAPTAINwpic.docx | F57: 2018-03-25 06:08:41 | G57: attachments/4463052.docx
A58: 4519389 | C58: Other Resume | D58: =IFERROR(INDEX(Types!B:B, MATCH(C58,Types!A:A, 0)), "") -> Other | E58: PUCCICAPTAINRES2.18.docx | F58: 2018-03-14 05:37:53 | G58: attachments/4463051.docx
A59: 4519389 | C59: CoverLetter | D59: =IFERROR(INDEX(Types!B:B, MATCH(C59,Types!A:A, 0)), "") -> Other / Unique | E59: USCG License reduced.pdf | F59: 2018-03-04 10:37:02 | G59: attachments/4463050.pdf
A60: 4519389 | C60: Other Resume | D60: =IFERROR(INDEX(Types!B:B, MATCH(C60,Types!A:A, 0)), "") -> Other | E60: PUCCICAPTAINRES2.18.docx | F60: 2018-03-04 10:32:41 | G60: attachments/4463049.docx
A61: 4519389 | C61: Other Resume | D61: =IFERROR(INDEX(Types!B:B, MATCH(C61,Types!A:A, 0)), "") -> Other | E61: PUCCICAPTAINRES10.17.doc | F61: 2017-11-10 14:27:09 | G61: attachments/4463048.doc
... A555: 4520175 | C555: Reference | D555: =IFERROR(INDEX(Types!B:B, MATCH(C555,Types!A:A, 0)), "") -> Reference | E555: Zanzibar_Murphy reference letter.docx | F555: 2019-07-23 13:08:10 | G555: attachments/5683540.docx
A556: 4520175 | B556: 2021-05-08 00:00:00 | C556: Marine Medical Certificate / ENG1 | D556: =IFERROR(INDEX(Types!B:B, MATCH(C556,Types!A:A, 0)), "") -> Medical | E556: USCG Medical Certificate.pdf | F556: 2019-05-14 13:52:33 | G556: attachments/5228646.pdf
A557: 4520175 | B557: 2025-02-03 00:00:00 | C557: Deck License | D557: =IFERROR(INDEX(Types!B:B, MATCH(C557,Types!A:A, 0)), "") -> CoC | E557: License_STCW_Medical_TWIC.pdf | F557: 2019-02-25 09:01:54 | G557: attachments/4488935.pdf
A558: 4520175 | C558: Resume | D558: =IFERROR(INDEX(Types!B:B, MATCH(C558,Types!A:A, 0)), "") -> CV | E558: Michael Murphy Resume Jan 2019.pdf | F558: 2019-02-22 15:36:59 | G558: attachments/4488934.pdf
A559: 4520175 | C559: Reference | D559: =IFERROR(INDEX(Types!B:B, MATCH(C559,Types!A:A, 0)), "") -> Reference | E559: Legendary Capt Michael Murphy letter of recommenda.pdf | F559: 2019-02-22 15:36:44 | G559: attachments/4488933.pdf
A560: 4520175 | C560: Other Resume | D560: =IFERROR(INDEX(Types!B:B, MATCH(C560,Types!A:A, 0)), "") -> Other | E560: Michael Murphy Resume 2016 Ft Lauderdale.docx | F560: 2017-08-23 08:59:33 | G560: attachments/4488932.docx
A561: 4520175 | C561: Other Resume | D561: =IFERROR(INDEX(Types!B:B, MATCH(C561,Types!A:A, 0)), "") -> Other | E561: Michael Murphy Resume 2 pg Feb 2015.pdf | F561: 2015-02-12 08:53:32 | G561: attachments/4488836.pdf
A562: 4520175 | C562: CoverLetter | D562: =IFERROR(INDEX(Types!B:B, MATCH(C562,Types!A:A, 0)), "") -> Other / Unique | E562: Signed Cover Letter.pdf | F562: 2015-02-12 08:53:32 | G562: attachments/4488835.pdf
A563: 4520175 | C563: Marine Medical Certificate / ENG1 | D563: =IFERROR(INDEX(Types!B:B, MATCH(C563,Types!A:A, 0)), "") -> Medical | E563: MMC Medical Evaluation.pdf | F563: 2014-08-18 15:37:06 | G563: attachments/4488734.pdf
A564: 4520175 | C564: References | D564: =IFERROR(INDEX(Types!B:B, MATCH(C564,Types!A:A, 0)), "") -> Reference | E564: Crew verbal reference April 29th 2014.docx | F564: 2014-04-29 10:29:36 | G564: attachments/4488732.docx
A565: 4520175 | C565: Other Resume | D565: =IFERROR(INDEX(Types!B:B, MATCH(C565,Types!A:A, 0)), "") -> Other | E565: Murphy-Michael 2014.docx | F565: 2014-03-21 07:55:41 | G565: attachments/4488731.docx
A566: 4520175 | C566: Other Resume | D566: =IFERROR(INDEX(Types!B:B, MATCH(C566,Types!A:A, 0)), "") -> Other | E566: Murphy-Michael_pic2(2)_try.pdf | F566: 2013-09-04 10:40:19 | G566: attachments/4488730.pdf
A567: 4520175 | C567: File | D567: =IFERROR(INDEX(Types!B:B, MATCH(C567,Types!A:A, 0)), "") -> Other | E567: Additional information.doc | F567: 2013-08-14 12:52:28 | G567: attachments/4488706.doc
...

Sheet Types
A1: Category | B1: Type
A2: Resume | B2: CV
A3: STCW | B3: STCW
A4: Marine Medical Certificate / ENG1 | B4: Medical
A5: Medical Certificate | B5: Medical
A6: Passport | B6: Passport
A7: EU Residence Permit | B7: Passport
A8: Visa | B8: Passport
A9: Visa B1B2 | B9: Passport
A10: TWIC Card - US | B10: Passport
A11: B1/B2 visa | B11: Passport
A12: Visa | B12: Passport
... A42: Proposal View Data | B42: ???
